2019-04-28 14:38:51,752 ERROR: Exception on /edit_profile [POST] [in /home/mufo/.virtualenvs/bsrh/lib/python3.6/site-packages/flask/app.py:1761]
Traceback (most recent call last):
  File "/home/mufo/.virtualenvs/bsrh/lib/python3.6/site-packages/sqlalchemy/engine/base.py", line 1236, in _execute_context
    cursor, statement, parameters, context
  File "/home/mufo/.virtualenvs/bsrh/lib/python3.6/site-packages/sqlalchemy/engine/default.py", line 536, in do_execute
    cursor.execute(statement, parameters)
sqlite3.IntegrityError: UNIQUE constraint failed: user.username

The above exception was the direct cause of the following exception:

Traceback (most recent call last):
  File "/home/mufo/.virtualenvs/bsrh/lib/python3.6/site-packages/flask/app.py", line 2292, in wsgi_app
    response = self.full_dispatch_request()
  File "/home/mufo/.virtualenvs/bsrh/lib/python3.6/site-packages/flask/app.py", line 1815, in full_dispatch_request
    rv = self.handle_user_exception(e)
  File "/home/mufo/.virtualenvs/bsrh/lib/python3.6/site-packages/flask/app.py", line 1718, in handle_user_exception
    reraise(exc_type, exc_value, tb)
  File "/home/mufo/.virtualenvs/bsrh/lib/python3.6/site-packages/flask/_compat.py", line 35, in reraise
    raise value
  File "/home/mufo/.virtualenvs/bsrh/lib/python3.6/site-packages/flask/app.py", line 1813, in full_dispatch_request
    rv = self.dispatch_request()
  File "/home/mufo/.virtualenvs/bsrh/lib/python3.6/site-packages/flask/app.py", line 1799, in dispatch_request
    return self.view_functions[rule.endpoint](**req.view_args)
  File "/home/mufo/.virtualenvs/bsrh/lib/python3.6/site-packages/flask_login/utils.py", line 261, in decorated_view
    return func(*args, **kwargs)
  File "/home/mufo/FlaskProjects/BSRH/app/routes.py", line 113, in edit_profile
    db.session.commit()
  File "/home/mufo/.virtualenvs/bsrh/lib/python3.6/site-packages/sqlalchemy/orm/scoping.py", line 162, in do
    return getattr(self.registry(), name)(*args, **kwargs)
  File "/home/mufo/.virtualenvs/bsrh/lib/python3.6/site-packages/sqlalchemy/orm/session.py", line 1023, in commit
    self.transaction.commit()
  File "/home/mufo/.virtualenvs/bsrh/lib/python3.6/site-packages/sqlalchemy/orm/session.py", line 487, in commit
    self._prepare_impl()
  File "/home/mufo/.virtualenvs/bsrh/lib/python3.6/site-packages/sqlalchemy/orm/session.py", line 466, in _prepare_impl
    self.session.flush()
  File "/home/mufo/.virtualenvs/bsrh/lib/python3.6/site-packages/sqlalchemy/orm/session.py", line 2436, in flush
    self._flush(objects)
  File "/home/mufo/.virtualenvs/bsrh/lib/python3.6/site-packages/sqlalchemy/orm/session.py", line 2574, in _flush
    transaction.rollback(_capture_exception=True)
  File "/home/mufo/.virtualenvs/bsrh/lib/python3.6/site-packages/sqlalchemy/util/langhelpers.py", line 67, in __exit__
    compat.reraise(exc_type, exc_value, exc_tb)
  File "/home/mufo/.virtualenvs/bsrh/lib/python3.6/site-packages/sqlalchemy/util/compat.py", line 277, in reraise
    raise value
  File "/home/mufo/.virtualenvs/bsrh/lib/python3.6/site-packages/sqlalchemy/orm/session.py", line 2534, in _flush
    flush_context.execute()
  File "/home/mufo/.virtualenvs/bsrh/lib/python3.6/site-packages/sqlalchemy/orm/unitofwork.py", line 416, in execute
    rec.execute(self)
  File "/home/mufo/.virtualenvs/bsrh/lib/python3.6/site-packages/sqlalchemy/orm/unitofwork.py", line 583, in execute
    uow,
  File "/home/mufo/.virtualenvs/bsrh/lib/python3.6/site-packages/sqlalchemy/orm/persistence.py", line 236, in save_obj
    update,
  File "/home/mufo/.virtualenvs/bsrh/lib/python3.6/site-packages/sqlalchemy/orm/persistence.py", line 976, in _emit_update_statements
    statement, multiparams
  File "/home/mufo/.virtualenvs/bsrh/lib/python3.6/site-packages/sqlalchemy/engine/base.py", line 980, in execute
    return meth(self, multiparams, params)
  File "/home/mufo/.virtualenvs/bsrh/lib/python3.6/site-packages/sqlalchemy/sql/elements.py", line 273, in _execute_on_connection
    return connection._execute_clauseelement(self, multiparams, params)
  File "/home/mufo/.virtualenvs/bsrh/lib/python3.6/site-packages/sqlalchemy/engine/base.py", line 1099, in _execute_clauseelement
    distilled_params,
  File "/home/mufo/.virtualenvs/bsrh/lib/python3.6/site-packages/sqlalchemy/engine/base.py", line 1240, in _execute_context
    e, statement, parameters, cursor, context
  File "/home/mufo/.virtualenvs/bsrh/lib/python3.6/site-packages/sqlalchemy/engine/base.py", line 1458, in _handle_dbapi_exception
    util.raise_from_cause(sqlalchemy_exception, exc_info)
  File "/home/mufo/.virtualenvs/bsrh/lib/python3.6/site-packages/sqlalchemy/util/compat.py", line 296, in raise_from_cause
    reraise(type(exception), exception, tb=exc_tb, cause=cause)
  File "/home/mufo/.virtualenvs/bsrh/lib/python3.6/site-packages/sqlalchemy/util/compat.py", line 276, in reraise
    raise value.with_traceback(tb)
  File "/home/mufo/.virtualenvs/bsrh/lib/python3.6/site-packages/sqlalchemy/engine/base.py", line 1236, in _execute_context
    cursor, statement, parameters, context
  File "/home/mufo/.virtualenvs/bsrh/lib/python3.6/site-packages/sqlalchemy/engine/default.py", line 536, in do_execute
    cursor.execute(statement, parameters)
sqlalchemy.exc.IntegrityError: (sqlite3.IntegrityError) UNIQUE constraint failed: user.username [SQL: 'UPDATE user SET username=?, about_me=? WHERE user.id = ?'] [parameters: ('susan', 'I a zbyszek and y keyboard is fuked', 2)] (Background on this error at: http://sqlalche.me/e/gkpj)
2019-04-28 15:20:08,814 INFO: BSRH startup [in /home/mufo/FlaskProjects/BSRH/app/__init__.py:47]
2019-04-28 15:20:09,302 INFO: BSRH startup [in /home/mufo/FlaskProjects/BSRH/app/__init__.py:47]
2019-04-28 19:49:30,243 INFO: BSRH startup [in /home/mufo/FlaskProjects/BSRH/app/__init__.py:47]
2019-04-28 19:49:30,788 INFO: BSRH startup [in /home/mufo/FlaskProjects/BSRH/app/__init__.py:47]
2019-05-16 16:48:11,024 INFO: BSRH startup [in /home/mufo/FlaskProjects/BSRH/app/__init__.py:47]
2019-05-16 16:51:11,209 INFO: BSRH startup [in /home/mufo/FlaskProjects/BSRH/app/__init__.py:47]
2019-05-16 16:52:45,875 INFO: BSRH startup [in /home/mufo/FlaskProjects/BSRH/app/__init__.py:47]
2019-05-16 16:55:06,574 INFO: BSRH startup [in /home/mufo/FlaskProjects/BSRH/app/__init__.py:47]
2019-05-16 17:04:18,750 INFO: BSRH startup [in /home/mufo/FlaskProjects/BSRH/app/__init__.py:47]
2019-05-16 17:06:18,729 INFO: BSRH startup [in /home/mufo/FlaskProjects/BSRH/app/__init__.py:47]
2019-05-16 17:14:37,361 INFO: BSRH startup [in /home/mufo/FlaskProjects/BSRH/app/__init__.py:47]
2019-05-16 17:40:52,993 INFO: BSRH startup [in /home/mufo/FlaskProjects/BSRH/app/__init__.py:47]
2019-07-01 11:29:04,483 INFO: BSRH startup [in /home/mufo/FlaskProjects/BSRH/app/__init__.py:51]
2019-07-01 11:29:10,817 ERROR: Exception on /reset_password_request [POST] [in /home/mufo/.virtualenvs/bsrh/lib/python3.6/site-packages/flask/app.py:1780]
Traceback (most recent call last):
  File "/home/mufo/.virtualenvs/bsrh/lib/python3.6/site-packages/flask_mail.py", line 492, in send
    message.send(connection)
  File "/home/mufo/.virtualenvs/bsrh/lib/python3.6/site-packages/flask_mail.py", line 427, in send
    connection.send(self)
  File "/home/mufo/.virtualenvs/bsrh/lib/python3.6/site-packages/flask_mail.py", line 192, in send
    message.rcpt_options)
  File "/usr/lib/python3.6/smtplib.py", line 852, in sendmail
    self.ehlo_or_helo_if_needed()
  File "/usr/lib/python3.6/smtplib.py", line 600, in ehlo_or_helo_if_needed
    if not (200 <= self.ehlo()[0] <= 299):
  File "/usr/lib/python3.6/smtplib.py", line 440, in ehlo
    self.putcmd(self.ehlo_msg, name or self.local_hostname)
  File "/usr/lib/python3.6/smtplib.py", line 367, in putcmd
    self.send(str)
  File "/usr/lib/python3.6/smtplib.py", line 359, in send
    raise SMTPServerDisconnected('please run connect() first')
smtplib.SMTPServerDisconnected: please run connect() first

During handling of the above exception, another exception occurred:

Traceback (most recent call last):
  File "/home/mufo/.virtualenvs/bsrh/lib/python3.6/site-packages/flask/app.py", line 2311, in wsgi_app
    response = self.full_dispatch_request()
  File "/home/mufo/.virtualenvs/bsrh/lib/python3.6/site-packages/flask/app.py", line 1834, in full_dispatch_request
    rv = self.handle_user_exception(e)
  File "/home/mufo/.virtualenvs/bsrh/lib/python3.6/site-packages/flask/app.py", line 1737, in handle_user_exception
    reraise(exc_type, exc_value, tb)
  File "/home/mufo/.virtualenvs/bsrh/lib/python3.6/site-packages/flask/_compat.py", line 36, in reraise
    raise value
  File "/home/mufo/.virtualenvs/bsrh/lib/python3.6/site-packages/flask/app.py", line 1832, in full_dispatch_request
    rv = self.dispatch_request()
  File "/home/mufo/.virtualenvs/bsrh/lib/python3.6/site-packages/flask/app.py", line 1818, in dispatch_request
    return self.view_functions[rule.endpoint](**req.view_args)
  File "/home/mufo/FlaskProjects/BSRH/app/routes.py", line 102, in reset_password_request
    send_password_reset_email(user)
  File "/home/mufo/FlaskProjects/BSRH/app/email.py", line 21, in send_password_reset_email
    user=user, token=token))
  File "/home/mufo/FlaskProjects/BSRH/app/email.py", line 10, in send_email
    mail.send(msg)
  File "/home/mufo/.virtualenvs/bsrh/lib/python3.6/site-packages/flask_mail.py", line 492, in send
    message.send(connection)
  File "/home/mufo/.virtualenvs/bsrh/lib/python3.6/site-packages/flask_mail.py", line 152, in __exit__
    self.host.quit()
  File "/usr/lib/python3.6/smtplib.py", line 984, in quit
    res = self.docmd("quit")
  File "/usr/lib/python3.6/smtplib.py", line 420, in docmd
    self.putcmd(cmd, args)
  File "/usr/lib/python3.6/smtplib.py", line 367, in putcmd
    self.send(str)
  File "/usr/lib/python3.6/smtplib.py", line 359, in send
    raise SMTPServerDisconnected('please run connect() first')
smtplib.SMTPServerDisconnected: please run connect() first
2019-07-01 11:31:03,943 INFO: BSRH startup [in /home/mufo/FlaskProjects/BSRH/app/__init__.py:51]
